Workbook

Sheet TTC Ridership Forecasting  ANS 
A1: TTC Annual Ridership — Forecasting Models (4-yr MA, 4-yr WMA, Exponential Smoothing)
A2: Rule: All final results rounded to 3 decimal places. Rounded values are reused in subsequent calculations.
A3: α (alpha) = | B3: 0.29 | C3: Weights (most→least recent): | D3: 5 | E3: 4 | F3: 2 | G3: 1 | H3: ← W1, W2, W3, W4 (sum = 12)
A5: Year | B5: Revenue (millions) | C5: 4-yr MA Forecast | D5: MA |Error| | E5: 4-yr WMA Forecast | F5: WMA |Error| | G5: ES Forecast (α=0.29) | H5: ES |Error|
A6: 2014 | B6: 533.7 | C6: — | D6: — | E6: — | F6: — | G6: — | H6: —
A7: 2015 | B7: 520.5 | C7: — | D7: — | E7: — | F7: — | G7: =ROUND(B6,3) -> 533.7 | H7: =ABS(B7-G7) -> 13.2
A8: 2016 | B8: 528.9 | C8: — | D8: — | E8: — | F8: — | G8: =ROUND($B$3*B7+(1-$B$3)*G7,3) -> 529.872 | H8: =ABS(B8-G8) -> 0.972
A9: 2017 | B9: 524 | C9: — | D9: — | E9: — | F9: — | G9: =ROUND($B$3*B8+(1-$B$3)*G8,3) -> 529.59 | H9: =ABS(B9-G9) -> 5.59
A10: 2018 | B10: 537.7 | C10: =ROUND(AVERAGE(B6:B9),3) -> 526.775 | D10: =ABS(B10-C10) -> 10.925 | E10: =ROUND(($D$3*B9+$E$3*B8+$F$3*B7+$G$3*B6)/SUM($D$3:$G$3),3) -> 525.858 | F10: =ABS(B10-E10) -> 11.842 | G10: =ROUND($B$3*B9+(1-$B$3)*G9,3) -> 527.969 | H10: =ABS(B10-G10) -> 9.731
A11: 2019 | B11: 533.5 | C11: =ROUND(AVERAGE(B7:B10),3) -> 527.775 | D11: =ABS(B11-C11) -> 5.725 | E11: =ROUND(($D$3*B10+$E$3*B9+$F$3*B8+$G$3*B7)/SUM($D$3:$G$3),3) -> 530.233 | F11: =ABS(B11-E11) -> 3.267 | G11: =ROUND($B$3*B10+(1-$B$3)*G10,3) -> 530.791 | H11: =ABS(B11-G11) -> 2.709
A12: 2020 | B12: 322.9 | C12: =ROUND(AVERAGE(B8:B11),3) -> 531.025 | D12: =ABS(B12-C12) -> 208.125 | E12: =ROUND(($D$3*B11+$E$3*B10+$F$3*B9+$G$3*B8)/SUM($D$3:$G$3),3) -> 532.933 | F12: =ABS(B12-E12) -> 210.033 | G12: =ROUND($B$3*B11+(1-$B$3)*G11,3) -> 531.577 | H12: =ABS(B12-G12) -> 208.677
A13: 2021 | B13: ← Forecast | C13: =ROUND(AVERAGE(B9:B12),3) -> 479.525 | D13: — | E13: =ROUND(($D$3*B12+$E$3*B11+$F$3*B10+$G$3*B9)/SUM($D$3:$G$3),3) -> 445.658 | F13: — | G13: =ROUND($B$3*B12+(1-$B$3)*G12,3) -> 471.061 | H13: —
A15: Mean Absolute Deviation (MAD) — Calculated over years with forecasts available (2018–2020, n=3)
A16: NOTE: MAD errors are NOT rounded during intermediate steps — only the final MAD is rounded to 3dp
A17: 4-yr Moving Average MAD | C17: =ROUND(AVERAGE(D10:D12),3) -> 74.925 | E17: ← Final MAD (rounded to 3dp)
A18: 4-yr Weighted MA MAD | C18: =ROUND(AVERAGE(F10:F12),3) -> 75.047 | E18: ← Final MAD (rounded to 3dp)
A19: Exponential Smoothing MAD | C19: =ROUND(AVERAGE(H10:H12),3) -> 73.706 | E19: ← Final MAD (rounded to 3dp)
A21: Best Method (lowest MAD): | C21: =IF(AND(C17<=C18,C17<=C19),"4-yr Moving Average",IF(AND(C18<=C17,C18<=C19),"4-yr Weighted MA","Exponential Smoothing (α=0.29)")) -> Exponential Smoothing (α=0.29)

Sheet Regression Model
A1: Sal's Sandwiches — Linear Regression Model (Trend + Seasonality)
A2: Model: ŷ = b₀ + b₁·X₁ + b₂·X₂ + b₃·X₃ + b₄·X₄ | X₁=time, X₂=S1(10:30-11:30), X₃=S2(11:30-12:30), X₄=S3(12:30-1:30) [Base=S4: 1:30-2:30]
A4: Regression Coefficients (Rounded to 1 decimal)
A5: b₀ (Intercept) | B5: 1.5 | C5: ← Base intercept (when all dummies=0, t=0)
A6: b₁ (Trend X₁) | B6: 0.5 | C6: ← Customer increase per time period
A7: b₂ (Season 1, X₂) | B7: 14.4 | C7: ← Lift vs base for 10:30–11:30am
A8: b₃ (Season 2, X₃) | B8: 52.6 | C8: ← Lift vs base for 11:30am–12:30pm
A9: b₄ (Season 3, X₄) | B9: 36.7 | C9: ← Lift vs base for 12:30–1:30pm
A11: Equation: ŷ = 1.5 + 0.5·X₁ + 14.4·X₂ + 52.6·X₃ + 36.7·X₄
A13: Week 1 Forecasts & MAPE
A14: t | B14: Day | C14: Time Period | D14: Actual | E14: X₂ (S1) | F14: X₃ (S2) | G14: X₄ (S3) | H14: Forecast ŷ | I14: |Actual - ŷ| | J14: |% Error|
A15: 1 | B15: Monday | C15: 10:30am-11:30am | D15: 14 | E15: 1 | F15: 0 | G15: 0 | H15: =ROUND($B$5 + $B$6*A15 + $B$7*E15 + $B$8*F15 + $B$9*G15, 1) -> 16.4 | I15: =ABS(D15-H15) -> 2.4 | J15: =ABS(D15-($B$5+$B$6*A15+$B$7*E15+$B$8*F15+$B$9*G15))/D15 -> 0.17142857
A16: 2 | B16: Monday | C16: 11:30am-12:30pm | D16: 69 | E16: 0 | F16: 1 | G16: 0 | H16: =ROUND($B$5 + $B$6*A16 + $B$7*E16 + $B$8*F16 + $B$9*G16, 1) -> 55.1 | I16: =ABS(D16-H16) -> 13.9 | J16: =ABS(D16-($B$5+$B$6*A16+$B$7*E16+$B$8*F16+$B$9*G16))/D16 -> 0.20144928
A17: 3 | B17: Monday | C17: 12:30pm-1:30pm | D17: 35 | E17: 0 | F17: 0 | G17: 1 | H17: =ROUND($B$5 + $B$6*A17 + $B$7*E17 + $B$8*F17 + $B$9*G17, 1) -> 39.7 | I17: =ABS(D17-H17) -> 4.7 | J17: =ABS(D17-($B$5+$B$6*A17+$B$7*E17+$B$8*F17+$B$9*G17))/D17 -> 0.13428571
A18: 4 | B18: Monday | C18: 1:30pm-2:30pm | D18: 6 | E18: 0 | F18: 0 | G18: 0 | H18: =ROUND($B$5 + $B$6*A18 + $B$7*E18 + $B$8*F18 + $B$9*G18, 1) -> 3.5 | I18: =ABS(D18-H18) -> 2.5 | J18: =ABS(D18-($B$5+$B$6*A18+$B$7*E18+$B$8*F18+$B$9*G18))/D18 -> 0.41666667
A19: 5 | B19: Tuesday | C19: 10:30am-11:30am | D19: 14 | E19: 1 | F19: 0 | G19: 0 | H19: =ROUND($B$5 + $B$6*A19 + $B$7*E19 + $B$8*F19 + $B$9*G19, 1) -> 18.4 | I19: =ABS(D19-H19) -> 4.4 | J19: =ABS(D19-($B$5+$B$6*A19+$B$7*E19+$B$8*F19+$B$9*G19))/D19 -> 0.31428571
A20: 6 | B20: Tuesday | C20: 11:30am-12:30pm | D20: 49 | E20: 0 | F20: 1 | G20: 0 | H20: =ROUND($B$5 + $B$6*A20 + $B$7*E20 + $B$8*F20 + $B$9*G20, 1) -> 57.1 | I20: =ABS(D20-H20) -> 8.1 | J20: =ABS(D20-($B$5+$B$6*A20+$B$7*E20+$B$8*F20+$B$9*G20))/D20 -> 0.16530612
A21: 7 | B21: Tuesday | C21: 12:30pm-1:30pm | D21: 38 | E21: 0 | F21: 0 | G21: 1 | H21: =ROUND($B$5 + $B$6*A21 + $B$7*E21 + $B$8*F21 + $B$9*G21, 1) -> 41.7 | I21: =ABS(D21-H21) -> 3.7 | J21: =ABS(D21-($B$5+$B$6*A21+$B$7*E21+$B$8*F21+$B$9*G21))/D21 -> 0.097368421
A22: 8 | B22: Tuesday | C22: 1:30pm-2:30pm | D22: 5 | E22: 0 | F22: 0 | G22: 0 | H22: =ROUND($B$5 + $B$6*A22 + $B$7*E22 + $B$8*F22 + $B$9*G22, 1) -> 5.5 | I22: =ABS(D22-H22) -> 0.5 | J22: =ABS(D22-($B$5+$B$6*A22+$B$7*E22+$B$8*F22+$B$9*G22))/D22 -> 0.1
A23: 9 | B23: Wednesday | C23: 10:30am-11:30am | D23: 22 | E23: 1 | F23: 0 | G23: 0 | H23: =ROUND($B$5 + $B$6*A23 + $B$7*E23 + $B$8*F23 + $B$9*G23, 1) -> 20.4 | I23: =ABS(D23-H23) -> 1.6 | J23: =ABS(D23-($B$5+$B$6*A23+$B$7*E23+$B$8*F23+$B$9*G23))/D23 -> 0.072727273
A24: 10 | B24: Wednesday | C24: 11:30am-12:30pm | D24: 65 | E24: 0 | F24: 1 | G24: 0 | H24: =ROUND($B$5 + $B$6*A24 + $B$7*E24 + $B$8*F24 + $B$9*G24, 1) -> 59.1 | I24: =ABS(D24-H24) -> 5.9 | J24: =ABS(D24-($B$5+$B$6*A24+$B$7*E24+$B$8*F24+$B$9*G24))/D24 -> 0.090769231
A25: 11 | B25: Wednesday | C25: 12:30pm-1:30pm | D25: 35 | E25: 0 | F25: 0 | G25: 1 | H25: =ROUND($B$5 + $B$6*A25 + $B$7*E25 + $B$8*F25 + $B$9*G25, 1) -> 43.7 | I25: =ABS(D25-H25) -> 8.7 | J25: =ABS(D25-($B$5+$B$6*A25+$B$7*E25+$B$8*F25+$B$9*G25))/D25 -> 0.24857143
A26: 12 | B26: Wednesday | C26: 1:30pm-2:30pm | D26: 7 | E26: 0 | F26: 0 | G26: 0 | H26: =ROUND($B$5 + $B$6*A26 + $B$7*E26 + $B$8*F26 + $B$9*G26, 1) -> 7.5 | I26: =ABS(D26-H26) -> 0.5 | J26: =ABS(D26-($B$5+$B$6*A26+$B$7*E26+$B$8*F26+$B$9*G26))/D26 -> 0.071428571
... A34: 20 | B34: Friday | C34: 1:30pm-2:30pm | D34: 9 | E34: 0 | F34: 0 | G34: 0 | H34: =ROUND($B$5 + $B$6*A34 + $B$7*E34 + $B$8*F34 + $B$9*G34, 1) -> 11.5 | I34: =ABS(D34-H34) -> 2.5 | J34: =ABS(D34-($B$5+$B$6*A34+$B$7*E34+$B$8*F34+$B$9*G34))/D34 -> 0.27777778
A35: MAPE | H35: =ROUND(AVERAGE(J15:J34)*100,2) -> 15.56 | I35: %
A37: Wednesday — Week 2 Forecasts (t = 29 to 32)
A38: t | B38: Day | C38: Time Period | D38: X₂ | E38: X₃ | F38: X₄ | G38: Forecast ŷ
A39: 29 | B39: Wednesday | C39: 10:30am-11:30am | D39: 1 | E39: 0 | F39: 0 | G39: =ROUND($B$5+$B$6*A39+$B$7*D39+$B$8*E39+$B$9*F39,1) -> 30.4
A40: 30 | B40: Wednesday | C40: 11:30am-12:30pm | D40: 0 | E40: 1 | F40: 0 | G40: =ROUND($B$5+$B$6*A40+$B$7*D40+$B$8*E40+$B$9*F40,1) -> 69.1
A41: 31 | B41: Wednesday | C41: 12:30pm-1:30pm | D41: 0 | E41: 0 | F41: 1 | G41: =ROUND($B$5+$B$6*A41+$B$7*D41+$B$8*E41+$B$9*F41,1) -> 53.7
A42: 32 | B42: Wednesday | C42: 1:30pm-2:30pm | D42: 0 | E42: 0 | F42: 0 | G42: =ROUND($B$5+$B$6*A42+$B$7*D42+$B$8*E42+$B$9*F42,1) -> 17.5

Sheet Decomposition Mode l SAL ANS 2
A1: Sal's Sandwiches — Decomposition Model (Seasonal Indices + Linear Trend)
A3: Step 1 — Centered Moving Averages (CMA)
A4: t | B4: Day | C4: Time Period | D4: Actual (y) | E4: 4-pt MA (before) | F4: 4-pt MA (after) | G4: CMA | H4: Seasonal Ratio (y/CMA)
A5: 1 | B5: Monday | C5: 10:30am-11:30am | D5: 14 | E5: N/A | F5: N/A | G5: N/A | H5: N/A
A6: 2 | B6: Monday | C6: 11:30am-12:30pm | D6: 69 | E6: N/A | F6: N/A | G6: N/A | H6: N/A
A7: 3 | B7: Monday | C7: 12:30pm-1:30pm | D7: 35 | E7: =AVERAGE(D5:D8) -> 31 | F7: =AVERAGE(D6:D9) -> 31 | G7: =ROUND(AVERAGE(E7,F7),1) -> 31 | H7: =D7/G7 -> 1.1290323
A8: 4 | B8: Monday | C8: 1:30pm-2:30pm | D8: 6 | E8: =AVERAGE(D6:D9) -> 31 | F8: =AVERAGE(D7:D10) -> 26 | G8: =ROUND(AVERAGE(E8,F8),1) -> 28.5 | H8: =D8/G8 -> 0.21052632
A9: 5 | B9: Tuesday | C9: 10:30am-11:30am | D9: 14 | E9: =AVERAGE(D7:D10) -> 26 | F9: =AVERAGE(D8:D11) -> 26.75 | G9: =ROUND(AVERAGE(E9,F9),1) -> 26.4 | H9: =D9/G9 -> 0.53030303
A10: 6 | B10: Tuesday | C10: 11:30am-12:30pm | D10: 49 | E10: =AVERAGE(D8:D11) -> 26.75 | F10: =AVERAGE(D9:D12) -> 26.5 | G10: =ROUND(AVERAGE(E10,F10),1) -> 26.6 | H10: =D10/G10 -> 1.8421053
A11: 7 | B11: Tuesday | C11: 12:30pm-1:30pm | D11: 38 | E11: =AVERAGE(D9:D12) -> 26.5 | F11: =AVERAGE(D10:D13) -> 28.5 | G11: =ROUND(AVERAGE(E11,F11),1) -> 27.5 | H11: =D11/G11 -> 1.3818182
A12: 8 | B12: Tuesday | C12: 1:30pm-2:30pm | D12: 5 | E12: =AVERAGE(D10:D13) -> 28.5 | F12: =AVERAGE(D11:D14) -> 32.5 | G12: =ROUND(AVERAGE(E12,F12),1) -> 30.5 | H12: =D12/G12 -> 0.16393443
A13: 9 | B13: Wednesday | C13: 10:30am-11:30am | D13: 22 | E13: =AVERAGE(D11:D14) -> 32.5 | F13: =AVERAGE(D12:D15) -> 31.75 | G13: =ROUND(AVERAGE(E13,F13),1) -> 32.1 | H13: =D13/G13 -> 0.68535826
A14: 10 | B14: Wednesday | C14: 11:30am-12:30pm | D14: 65 | E14: =AVERAGE(D12:D15) -> 31.75 | F14: =AVERAGE(D13:D16) -> 32.25 | G14: =ROUND(AVERAGE(E14,F14),1) -> 32 | H14: =D14/G14 -> 2.03125
A15: 11 | B15: Wednesday | C15: 12:30pm-1:30pm | D15: 35 | E15: =AVERAGE(D13:D16) -> 32.25 | F15: =AVERAGE(D14:D17) -> 33.5 | G15: =ROUND(AVERAGE(E15,F15),1) -> 32.9 | H15: =D15/G15 -> 1.0638298
A16: 12 | B16: Wednesday | C16: 1:30pm-2:30pm | D16: 7 | E16: =AVERAGE(D14:D17) -> 33.5 | F16: =AVERAGE(D15:D18) -> 30 | G16: =ROUND(AVERAGE(E16,F16),1) -> 31.8 | H16: =D16/G16 -> 0.22012579
A17: 13 | B17: Thursday | C17: 10:30am-11:30am | D17: 27 | E17: =AVERAGE(D15:D18) -> 30 | F17: =AVERAGE(D16:D19) -> 36.5 | G17: =ROUND(AVERAGE(E17,F17),1) -> 33.3 | H17: =D17/G17 -> 0.81081081
A18: 14 | B18: Thursday | C18: 11:30am-12:30pm | D18: 51 | E18: =AVERAGE(D16:D19) -> 36.5 | F18: =AVERAGE(D17:D20) -> 37 | G18: =ROUND(AVERAGE(E18,F18),1) -> 36.8 | H18: =D18/G18 -> 1.3858696
... A22: 18 | B22: Friday | C22: 11:30am-12:30pm | D22: 60 | E22: =AVERAGE(D20:D23) -> 35.25 | F22: =AVERAGE(D21:D24) -> 35.25 | G22: =ROUND(AVERAGE(E22,F22),1) -> 35.3 | H22: =D22/G22 -> 1.6997167
A23: 19 | B23: Friday | C23: 12:30pm-1:30pm | D23: 48 | E23: N/A | F23: N/A | G23: N/A | H23: N/A
A24: 20 | B24: Friday | C24: 1:30pm-2:30pm | D24: 9 | E24: N/A | F24: N/A | G24: N/A | H24: N/A
A27: Step 2 — Seasonal Indices
A28: Method: Average seasonal ratios per season, then normalize so sum = 4
A29: Season | B29: Time Period | C29: Ratio 1 (t=3/4 or 5/6...) | D29: Ratio 2 | E29: Ratio 3 | F29: Average Ratio | G29: Avg Ratio (unrounded) | H29: Seasonal Index (rounded to 4dp)
A30: 1 | B30: 10:30–11:30am | C30: =H9 -> 0.53030303 | D30: =H13 -> 0.68535826 | E30: =H17 -> 0.81081081 | F30: =H21 -> 0.6504065 | G30: =AVERAGE(C30:F30) -> 0.66921965 | H30: =G30*4/SUM(G30:G33) -> 0.68146926
A31: 2 | B31: 11:30am–12:30pm | C31: =H10 -> 1.8421053 | D31: =H14 -> 2.03125 | E31: =H18 -> 1.3858696 | F31: =H22 -> 1.6997167 | G31: =AVERAGE(C31:F31) -> 1.7397354 | H31: =G31*4/SUM(G30:G33) -> 1.7715801
A32: 3 | B32: 12:30–1:30pm | C32: =H7 -> 1.1290323 | D32: =H11 -> 1.3818182 | E32: =H15 -> 1.0638298 | F32: =H19 -> 1.6666667 | G32: =AVERAGE(C32:F32) -> 1.3103367 | H32: =G32*4/SUM(G30:G33) -> 1.3343215
A33: 4 | B33: 1:30–2:30pm | C33: =H8 -> 0.21052632 | D33: =H12 -> 0.16393443 | E33: =H16 -> 0.22012579 | F33: =H20 -> 0.24064171 | G33: =AVERAGE(C33:F33) -> 0.20880706 | H33: =G33*4/SUM(G30:G33) -> 0.21262913
A35: Step 3 — Deseasonalized Values (y / SI)
A36: t | B36: Day | C36: Time Period | D36: Actual (y) | E36: Season | F36: SI Used | G36: Deseasonalized (y/SI)
A37: 1 | B37: Monday | C37: 10:30am-11:30am | D37: 14 | E37: S1 | F37: =$H$30 -> 0.68146926 | G37: =ROUND(D37/F37,1) -> 20.5
A38: 2 | B38: Monday | C38: 11:30am-12:30pm | D38: 69 | E38: S2 | F38: =$H$31 -> 1.7715801 | G38: =ROUND(D38/F38,1) -> 38.9
A39: 3 | B39: Monday | C39: 12:30pm-1:30pm | D39: 35 | E39: S3 | F39: =$H$32 -> 1.3343215 | G39: =ROUND(D39/F39,1) -> 26.2
A40: 4 | B40: Monday | C40: 1:30pm-2:30pm | D40: 6 | E40: S4 | F40: =$H$33 -> 0.21262913 | G40: =ROUND(D40/F40,1) -> 28.2
A41: 5 | B41: Tuesday | C41: 10:30am-11:30am | D41: 14 | E41: S1 | F41: =$H$30 -> 0.68146926 | G41: =ROUND(D41/F41,1) -> 20.5
A42: 6 | B42: Tuesday | C42: 11:30am-12:30pm | D42: 49 | E42: S2 | F42: =$H$31 -> 1.7715801 | G42: =ROUND(D42/F42,1) -> 27.7
A43: 7 | B43: Tuesday | C43: 12:30pm-1:30pm | D43: 38 | E43: S3 | F43: =$H$32 -> 1.3343215 | G43: =ROUND(D43/F43,1) -> 28.5
A44: 8 | B44: Tuesday | C44: 1:30pm-2:30pm | D44: 5 | E44: S4 | F44: =$H$33 -> 0.21262913 | G44: =ROUND(D44/F44,1) -> 23.5
A45: 9 | B45: Wednesday | C45: 10:30am-11:30am | D45: 22 | E45: S1 | F45: =$H$30 -> 0.68146926 | G45: =ROUND(D45/F45,1) -> 32.3
A46: 10 | B46: Wednesday | C46: 11:30am-12:30pm | D46: 65 | E46: S2 | F46: =$H$31 -> 1.7715801 | G46: =ROUND(D46/F46,1) -> 36.7
A47: 11 | B47: Wednesday | C47: 12:30pm-1:30pm | D47: 35 | E47: S3 | F47: =$H$32 -> 1.3343215 | G47: =ROUND(D47/F47,1) -> 26.2
...

Sheet Summary & Comparison ANS 2
A1: Sal's Sandwiches — Model Comparison Summary
A3: Regression Model
A4: Equation | B4: ŷ = 1.5 + 0.5·X₁ + 14.4·X₂ + 52.6·X₃ + 36.7·X₄
A5: b₀ (Intercept) | B5: ='Regression Model'!B5 -> 1.5
A6: b₁ (Trend) | B6: ='Regression Model'!B6 -> 0.5
A7: b₂ (Season 1: 10:30–11:30) | B7: ='Regression Model'!B7 -> 14.4
A8: b₃ (Season 2: 11:30–12:30) | B8: ='Regression Model'!B8 -> 52.6
A9: b₄ (Season 3: 12:30–1:30) | B9: ='Regression Model'!B9 -> 36.7
A10: MAPE | B10: ='Regression Model'!H35 -> 15.56
A13: Decomposition Model
A14: SI — 10:30–11:30am | B14: ='Decomposition Mode l SAL ANS 2'!H30 -> 0.68146926
A15: SI — 11:30am–12:30pm | B15: ='Decomposition Mode l SAL ANS 2'!H31 -> 1.7715801
A16: SI — 12:30–1:30pm | B16: ='Decomposition Mode l SAL ANS 2'!H32 -> 1.3343215
A17: SI — 1:30–2:30pm | B17: ='Decomposition Mode l SAL ANS 2'!H33 -> 0.21262913
A18: Trend Intercept | B18: ='Decomposition Mode l SAL ANS 2'!C60 -> 24
A19: Trend Slope | B19: ='Decomposition Mode l SAL ANS 2'!C61 -> 0.8
A20: MAPE | B20: ='Decomposition Mode l SAL ANS 2'!H86 -> 14.02
A23: Conclusion
A24: Better Model (lower MAPE): | B24: =IF(B10<B20,"Regression Model is better (lower MAPE)","Decomposition Model is better (lower MAPE)") -> Decomposition Model is better (lower MAPE)

Sheet Part A - Perceptron  ANS 3 
A1: Part A — Perceptron Algorithm (First 3 Updates)
A2: Update Rule: if y·(θ₁x₁ + θ₂x₂ + θ₀) ≤ 0 → θ = θ + y·[x₁, x₂, 1] | All values rounded to 4 decimal places
A3: Row | B3: x₁ | C3: x₂ | D3: y | E3: y(θ₁x₁ + θ₂x₂ + θ₀) | F3: θ₁ | G3: θ₂ | H3: θ₀
A4: Initialization | F4: 0 | G4: 0 | H4: 0
A5: Update 1 | B5: 10 | C5: 6 | D5: 1 | E5: =D5*(F4*B5+G4*C5+H4) -> 0 | F5: =ROUND(IF(E5<=0, F4+D5*B5, F4), 4) -> 10 | G5: =ROUND(IF(E5<=0, G4+D5*C5, G4), 4) -> 6 | H5: =ROUND(IF(E5<=0, H4+D5, H4), 4) -> 1
A6: Update 2 | B6: 8 | C6: 4 | D6: 1 | E6: =D6*(F5*B6+G5*C6+H5) -> 105 | F6: =ROUND(IF(E6<=0, F5+D6*B6, F5), 4) -> 10 | G6: =ROUND(IF(E6<=0, G5+D6*C6, G5), 4) -> 6 | H6: =ROUND(IF(E6<=0, H5+D6, H5), 4) -> 1
A7: Update 3 | B7: 7 | C7: 8 | D7: -1 | E7: =D7*(F6*B7+G6*C7+H6) -> -119 | F7: =ROUND(IF(E7<=0, F6+D7*B7, F6), 4) -> 3 | G7: =ROUND(IF(E7<=0, G6+D7*C7, G6), 4) -> -2 | H7: =ROUND(IF(E7<=0, H6+D7, H6), 4) -> 0

Sheet Part B - Training Error
A1: Part B — Training Error | Decision Boundary: 17x₁ − 24x₂ − 19 = 0
A2: Point | B2: x₁ | C2: x₂ | D2: y | E2: Score = 17x₁−24x₂−19 | F2: Prediction | G2: Correct?
A3: (10, 6, 1) | B3: 10 | C3: 6 | D3: 1 | E3: =17*B3-24*C3-19 -> 7 | F3: =IF(E3>0,1,-1) -> 1 | G3: =IF(F3=D3,"✓ Correct","✗ Wrong") -> ✓ Correct
A4: (8, 4, 1) | B4: 8 | C4: 4 | D4: 1 | E4: =17*B4-24*C4-19 -> 21 | F4: =IF(E4>0,1,-1) -> 1 | G4: =IF(F4=D4,"✓ Correct","✗ Wrong") -> ✓ Correct
A5: (7, 8, -1) | B5: 7 | C5: 8 | D5: -1 | E5: =17*B5-24*C5-19 -> -92 | F5: =IF(E5>0,1,-1) -> -1 | G5: =IF(F5=D5,"✓ Correct","✗ Wrong") -> ✓ Correct
A6: (7, 5, -1) | B6: 7 | C6: 5 | D6: -1 | E6: =17*B6-24*C6-19 -> -20 | F6: =IF(E6>0,1,-1) -> -1 | G6: =IF(F6=D6,"✓ Correct","✗ Wrong") -> ✓ Correct
A7: (4, 1, -1) | B7: 4 | C7: 1 | D7: -1 | E7: =17*B7-24*C7-19 -> 25 | F7: =IF(E7>0,1,-1) -> 1 | G7: =IF(F7=D7,"✓ Correct","✗ Wrong") -> ✗ Wrong
A8: (7, 2, 1) | B8: 7 | C8: 2 | D8: 1 | E8: =17*B8-24*C8-19 -> 52 | F8: =IF(E8>0,1,-1) -> 1 | G8: =IF(F8=D8,"✓ Correct","✗ Wrong") -> ✓ Correct
A9: Training Error Eₙ(h) = | E9: =ROUND(COUNTIF(G3:G8,"✗ Wrong")/6, 4) -> 0.1667 | F9: ← Final Answer

Sheet Part C - SGD
A1: Part C — SGD Updates | λ=1, η=1/(1+t), t starts at 0
A2: If y·score < 1: θ_new = θ_old·(1−η) + η·y·x | Else: θ_new = θ_old·(1−η) | Do NOT round η
A3: Row | B3: x₁ | C3: x₂ | D3: y | E3: t | F3: η = 1/(1+t) | G3: y·(θ₁x₁+θ₂x₂+θ₀) | H3: θ₁ | I3: θ₂ | J3: θ₀
A4: Initialization | G4: — | H4: 0 | I4: 0 | J4: 0
A5: Update 1 | B5: 7 | C5: 8 | D5: -1 | E5: 0 | F5: =1/(1+E5) -> 1 | G5: =D5*(H4*B5+I4*C5+J4) -> 0 | H5: =ROUND(IF(G5<1, H4*(1-F5)+F5*D5*B5, H4*(1-F5)), 4) -> -7 | I5: =ROUND(IF(G5<1, I4*(1-F5)+F5*D5*C5, I4*(1-F5)), 4) -> -8 | J5: =ROUND(IF(G5<1, J4*(1-F5)+F5*D5*1, J4*(1-F5)), 4) -> -1
A6: Update 2 | B6: 7 | C6: 8 | D6: -1 | E6: 1 | F6: =1/(1+E6) -> 0.5 | G6: =D6*(H5*B6+I5*C6+J5) -> 114 | H6: =ROUND(IF(G6<1, H5*(1-F6)+F6*D6*B6, H5*(1-F6)), 4) -> -3.5 | I6: =ROUND(IF(G6<1, I5*(1-F6)+F6*D6*C6, I5*(1-F6)), 4) -> -4 | J6: =ROUND(IF(G6<1, J5*(1-F6)+F6*D6*1, J5*(1-F6)), 4) -> -0.5
A7: Update 3 | B7: 10 | C7: 6 | D7: 1 | E7: 2 | F7: =1/(1+E7) -> 0.33333333 | G7: =D7*(H6*B7+I6*C7+J6) -> -59.5 | H7: =ROUND(IF(G7<1, H6*(1-F7)+F7*D7*B7, H6*(1-F7)), 4) -> 1 | I7: =ROUND(IF(G7<1, I6*(1-F7)+F7*D7*C7, I6*(1-F7)), 4) -> -0.6667 | J7: =ROUND(IF(G7<1, J6*(1-F7)+F7*D7*1, J6*(1-F7)), 4) -> 0

Sheet Part D - Objective Function
A1: Part D — SGD Objective Function | θ₁=0.3607, θ₂=−0.1803, θ₀=−0.4772, λ=1
A2: θ₁ | B2: 0.3607 | C2: θ₂ | D2: -0.1803 | E2: θ₀ | F2: -0.4772 | G2: λ | H2: 1
A3: Point | B3: x₁ | C3: x₂ | D3: y | E3: Score θ·x | F3: y·Score (margin) | G3: Hinge Loss max(0,1−margin)
A4: (10,6,1) | B4: 10 | C4: 6 | D4: 1 | E4: =$B$2*B4+$D$2*C4+$F$2 -> 2.048 | F4: =D4*E4 -> 2.048 | G4: =MAX(0,1-F4) -> 0
A5: (8,4,1) | B5: 8 | C5: 4 | D5: 1 | E5: =$B$2*B5+$D$2*C5+$F$2 -> 1.6872 | F5: =D5*E5 -> 1.6872 | G5: =MAX(0,1-F5) -> 0
A6: (7,8,-1) | B6: 7 | C6: 8 | D6: -1 | E6: =$B$2*B6+$D$2*C6+$F$2 -> 0.6053 | F6: =D6*E6 -> -0.6053 | G6: =MAX(0,1-F6) -> 1.6053
A7: (7,5,-1) | B7: 7 | C7: 5 | D7: -1 | E7: =$B$2*B7+$D$2*C7+$F$2 -> 1.1462 | F7: =D7*E7 -> -1.1462 | G7: =MAX(0,1-F7) -> 2.1462
A8: (4,1,-1) | B8: 4 | C8: 1 | D8: -1 | E8: =$B$2*B8+$D$2*C8+$F$2 -> 0.7853 | F8: =D8*E8 -> -0.7853 | G8: =MAX(0,1-F8) -> 1.7853
A9: (7,2,1) | B9: 7 | C9: 2 | D9: 1 | E9: =$B$2*B9+$D$2*C9+$F$2 -> 1.6871 | F9: =D9*E9 -> 1.6871 | G9: =MAX(0,1-F9) -> 0
A10: i. Average Hinge Loss = (1/n)·Σ Loss_h | G10: =ROUND(SUM(G4:G9)/6, 4) -> 0.9228
A11: ii. Regularization = (λ/2)·(θ₁² + θ₂²) [bias θ₀ NOT regularized] | G11: =ROUND($H$2/2*($B$2^2+$D$2^2), 4) -> 0.0813
A12: iii. J(θ₁,θ₂,θ₀) = Loss Term + Regularization Term | G12: =ROUND(G10+G11, 4) -> 1.0041
